Traceback (most recent call last):
  File "/home/murraybj/CHE498/QUBOBook/.venv/lib/python3.10/site-packages/nbclient/client.py", line 782, in _async_poll_for_reply
    msg = await ensure_async(self.kc.shell_channel.get_msg(timeout=new_timeout))
  File "/home/murraybj/CHE498/QUBOBook/.venv/lib/python3.10/site-packages/jupyter_core/utils/__init__.py", line 198, in ensure_async
    result = await obj
  File "/home/murraybj/CHE498/QUBOBook/.venv/lib/python3.10/site-packages/jupyter_client/channels.py", line 313, in get_msg
    raise Empty
_queue.Empty

During handling of the above exception, another exception occurred:

Traceback (most recent call last):
  File "/home/murraybj/CHE498/QUBOBook/.venv/lib/python3.10/site-packages/jupyter_cache/executors/utils.py", line 58, in single_nb_execution
    executenb(
  File "/home/murraybj/CHE498/QUBOBook/.venv/lib/python3.10/site-packages/nbclient/client.py", line 1314, in execute
    return NotebookClient(nb=nb, resources=resources, km=km, **kwargs).execute()
  File "/home/murraybj/CHE498/QUBOBook/.venv/lib/python3.10/site-packages/jupyter_core/utils/__init__.py", line 165, in wrapped
    return loop.run_until_complete(inner)
  File "/usr/lib/python3.10/asyncio/base_events.py", line 649, in run_until_complete
    return future.result()
  File "/home/murraybj/CHE498/QUBOBook/.venv/lib/python3.10/site-packages/nbclient/client.py", line 709, in async_execute
    await self.async_execute_cell(
  File "/home/murraybj/CHE498/QUBOBook/.venv/lib/python3.10/site-packages/nbclient/client.py", line 1005, in async_execute_cell
    exec_reply = await self.task_poll_for_reply
  File "/home/murraybj/CHE498/QUBOBook/.venv/lib/python3.10/site-packages/nbclient/client.py", line 806, in _async_poll_for_reply
    error_on_timeout_execute_reply = await self._async_handle_timeout(timeout, cell)
  File "/home/murraybj/CHE498/QUBOBook/.venv/lib/python3.10/site-packages/nbclient/client.py", line 856, in _async_handle_timeout
    raise CellTimeoutError.error_from_timeout_and_cell(
nbclient.exceptions.CellTimeoutError: A cell timed out while it was being executed, after 30 seconds.
The message was: Cell execution timed out.
Here is a preview of the cell contents:
-------------------
['s = 0.99', '# sweeps = list(chain(np.arange(1,10,1),np.arange(10,30,2), np.arange(30,50,5), np.arange(50,100,10) ,np.arange(100,1001,100)))', 'sweeps = list(chain(np.arange(1, 250, 1), np.arange(250, 1001, 10)))', "schedules = ['geometric','linear']", 'opt_energy = 5']
...
['            time_to_sol.append(time_s*math.log10(1-s)/math.log10(1-pr))', '        times.append(time_s)', "    results['p'][schedule] = probs", "    results['tts'][schedule] = time_to_sol", "    results['t'][schedule] = times"]
-------------------

