Traceback (most recent call last):
  File "/home/murraybj/CHE498/QUBOBook/.venv/lib/python3.10/site-packages/jupyter_cache/executors/utils.py", line 58, in single_nb_execution
    executenb(
  File "/home/murraybj/CHE498/QUBOBook/.venv/lib/python3.10/site-packages/nbclient/client.py", line 1314, in execute
    return NotebookClient(nb=nb, resources=resources, km=km, **kwargs).execute()
  File "/home/murraybj/CHE498/QUBOBook/.venv/lib/python3.10/site-packages/jupyter_core/utils/__init__.py", line 165, in wrapped
    return loop.run_until_complete(inner)
  File "/usr/lib/python3.10/asyncio/base_events.py", line 649, in run_until_complete
    return future.result()
  File "/home/murraybj/CHE498/QUBOBook/.venv/lib/python3.10/site-packages/nbclient/client.py", line 709, in async_execute
    await self.async_execute_cell(
  File "/home/murraybj/CHE498/QUBOBook/.venv/lib/python3.10/site-packages/nbclient/client.py", line 1062, in async_execute_cell
    await self._check_raise_for_error(cell, cell_index, exec_reply)
  File "/home/murraybj/CHE498/QUBOBook/.venv/lib/python3.10/site-packages/nbclient/client.py", line 918, in _check_raise_for_error
    raise CellExecutionError.from_cell_and_msg(cell, exec_reply_content)
nbclient.exceptions.CellExecutionError: An error occurred while executing the following cell:
------------------
# imports necessary packages to run on a DWAVE Machine
from pyqubo import Spin, Array, Placeholder, Constraint
import matplotlib.pyplot as plt
import networkx as nx
import dimod
import neal

# Misc. imports
import numpy as np
import random
import time
import os

# Connecting to DWAVE Account
os.environ['DWAVE_API_TOKEN'] = 'ADD YOUR DWAVE API KEY HERE'
------------------


[0;31m---------------------------------------------------------------------------[0m
[0;31mModuleNotFoundError[0m                       Traceback (most recent call last)
Cell [0;32mIn[2], line 2[0m
[1;32m      1[0m [38;5;66;03m# imports necessary packages to run on a DWAVE Machine[39;00m
[0;32m----> 2[0m [38;5;28;01mfrom[39;00m [38;5;21;01mpyqubo[39;00m [38;5;28;01mimport[39;00m Spin, Array, Placeholder, Constraint
[1;32m      3[0m [38;5;28;01mimport[39;00m [38;5;21;01mmatplotlib[39;00m[38;5;21;01m.[39;00m[38;5;21;01mpyplot[39;00m [38;5;28;01mas[39;00m [38;5;21;01mplt[39;00m
[1;32m      4[0m [38;5;28;01mimport[39;00m [38;5;21;01mnetworkx[39;00m [38;5;28;01mas[39;00m [38;5;21;01mnx[39;00m

[0;31mModuleNotFoundError[0m: No module named 'pyqubo'

